{"created": 1756811940.9533758, "duration": 1.9335098266601562, "exitcode": 1, "root": "/home/jayasree/e-commerce/full-stack-fastapi-template/backend", "environment": {}, "summary": {"failed": 20, "total": 20, "collected": 20}, "collectors": [{"nodeid": "", "outcome": "passed", "result": [{"nodeid": "test_passed1.py", "type": "Module"}, {"nodeid": "test_failed1.py", "type": "Module"}]}, {"nodeid": "test_passed1.py", "outcome": "passed", "result": []}, {"nodeid": "test_failed1.py", "outcome": "passed", "result": [{"nodeid": "test_failed1.py::test_create_user_positive_case", "type": "Function", "lineno": 180}, {"nodeid": "test_failed1.py::test_create_user_email_already_exists", "type": "Function", "lineno": 217}, {"nodeid": "test_failed1.py::test_create_user_empty_email", "type": "Function", "lineno": 251}, {"nodeid": "test_failed1.py::test_create_user_invalid_user_in_data", "type": "Function", "lineno": 287}, {"nodeid": "test_failed1.py::test_create_user_whitespace_email", "type": "Function", "lineno": 321}, {"nodeid": "test_failed1.py::test_create_user_emails_disabled", "type": "Function", "lineno": 357}, {"nodeid": "test_failed1.py::test_create_user_crud_create_user_raises_exception", "type": "Function", "lineno": 392}, {"nodeid": "test_failed1.py::test_create_user_email_is_none", "type": "Function", "lineno": 424}, {"nodeid": "test_failed1.py::test_create_user_generate_new_account_email_raises", "type": "Function", "lineno": 459}, {"nodeid": "test_failed1.py::test_create_user_send_email_raises", "type": "Function", "lineno": 494}, {"nodeid": "test_failed1.py::test_send_email_positive_case", "type": "Function", "lineno": 533}, {"nodeid": "test_failed1.py::test_send_email_emails_disabled", "type": "Function", "lineno": 577}, {"nodeid": "test_failed1.py::test_send_email_empty_email_to", "type": "Function", "lineno": 601}, {"nodeid": "test_failed1.py::test_send_email_empty_subject_and_html_content", "type": "Function", "lineno": 645}, {"nodeid": "test_failed1.py::test_send_email_invalid_email_address", "type": "Function", "lineno": 689}, {"nodeid": "test_failed1.py::test_send_email_smtp_host_is_none", "type": "Function", "lineno": 722}, {"nodeid": "test_failed1.py::test_send_email_smtp_port_is_zero", "type": "Function", "lineno": 755}, {"nodeid": "test_failed1.py::test_send_email_authentication_fails", "type": "Function", "lineno": 788}, {"nodeid": "test_failed1.py::test_send_email_conflicting_tls_ssl_settings", "type": "Function", "lineno": 821}, {"nodeid": "test_failed1.py::test_send_email_unexpected_message_send_exception", "type": "Function", "lineno": 854}]}], "tests": [{"nodeid": "test_failed1.py::test_create_user_positive_case", "lineno": 180, "outcome": "failed", "keywords": ["test_create_user_positive_case", "__wrapped__", "patchings", "test_failed1.py", "backend"], "setup": {"duration": 0.0004804860000149347, "outcome": "passed"}, "call": {"duration": 0.0005180329972063191, "outcome": "failed", "crash": {"path": "/usr/lib/python3.12/unittest/mock.py", "lineno": 1431, "message": "AttributeError: <module '__main__' from '/home/jayasree/e-commerce/venv/bin/pytest'> does not have the attribute 'crud'"}, "traceback": [{"path": "/usr/lib/python3.12/unittest/mock.py", "lineno": 1387, "message": ""}, {"path": "/usr/lib/python3.12/contextlib.py", "lineno": 137, "message": "in __enter__"}, {"path": "/usr/lib/python3.12/unittest/mock.py", "lineno": 1369, "message": "in decoration_helper"}, {"path": "/usr/lib/python3.12/contextlib.py", "lineno": 526, "message": "in enter_context"}, {"path": "/usr/lib/python3.12/unittest/mock.py", "lineno": 1458, "message": "in __enter__"}, {"path": "/usr/lib/python3.12/unittest/mock.py", "lineno": 1431, "message": "AttributeError"}], "longrepr": "args = ()\nkeywargs = {'mock_db_session': <test_failed1.MockDBSession object at 0x7715d650d2e0>}\n\n    @wraps(func)\n    def patched(*args, **keywargs):\n>       with self.decoration_helper(patched,\n                                    args,\n                                    keywargs) as (newargs, newkeywargs):\n\n/usr/lib/python3.12/unittest/mock.py:1387: \n_ _ _ _ _ _ _ _ _ _ _ _ _ _ _ _ _ _ _ _ _ _ _ _ _ _ _ _ _ _ _ _ _ _ _ _ _ _ _ _ \n/usr/lib/python3.12/contextlib.py:137: in __enter__\n    return next(self.gen)\n/usr/lib/python3.12/unittest/mock.py:1369: in decoration_helper\n    arg = exit_stack.enter_context(patching)\n/usr/lib/python3.12/contextlib.py:526: in enter_context\n    result = _enter(cm)\n/usr/lib/python3.12/unittest/mock.py:1458: in __enter__\n    original, local = self.get_original()\n_ _ _ _ _ _ _ _ _ _ _ _ _ _ _ _ _ _ _ _ _ _ _ _ _ _ _ _ _ _ _ _ _ _ _ _ _ _ _ _ \n\nself = <unittest.mock._patch object at 0x7715d401ba40>\n\n    def get_original(self):\n        target = self.getter()\n        name = self.attribute\n    \n        original = DEFAULT\n        local = False\n    \n        try:\n            original = target.__dict__[name]\n        except (AttributeError, KeyError):\n            original = getattr(target, name, DEFAULT)\n        else:\n            local = True\n    \n        if name in _builtins and isinstance(target, ModuleType):\n            self.create = True\n    \n        if not self.create and original is DEFAULT:\n>           raise AttributeError(\n                \"%s does not have the attribute %r\" % (target, name)\n            )\nE           AttributeError: <module '__main__' from '/home/jayasree/e-commerce/venv/bin/pytest'> does not have the attribute 'crud'\n\n/usr/lib/python3.12/unittest/mock.py:1431: AttributeError"}, "teardown": {"duration": 0.0006676619996142108, "outcome": "passed"}}, {"nodeid": "test_failed1.py::test_create_user_email_already_exists", "lineno": 217, "outcome": "failed", "keywords": ["test_create_user_email_already_exists", "__wrapped__", "patchings", "test_failed1.py", "backend"], "setup": {"duration": 0.0005215400015003979, "outcome": "passed"}, "call": {"duration": 0.00042291499994462356, "outcome": "failed", "crash": {"path": "/usr/lib/python3.12/unittest/mock.py", "lineno": 1431, "message": "AttributeError: <module '__main__' from '/home/jayasree/e-commerce/venv/bin/pytest'> does not have the attribute 'crud'"}, "traceback": [{"path": "/usr/lib/python3.12/unittest/mock.py", "lineno": 1387, "message": ""}, {"path": "/usr/lib/python3.12/contextlib.py", "lineno": 137, "message": "in __enter__"}, {"path": "/usr/lib/python3.12/unittest/mock.py", "lineno": 1369, "message": "in decoration_helper"}, {"path": "/usr/lib/python3.12/contextlib.py", "lineno": 526, "message": "in enter_context"}, {"path": "/usr/lib/python3.12/unittest/mock.py", "lineno": 1458, "message": "in __enter__"}, {"path": "/usr/lib/python3.12/unittest/mock.py", "lineno": 1431, "message": "AttributeError"}], "longrepr": "args = ()\nkeywargs = {'mock_db_session': <test_failed1.MockDBSession object at 0x7715d402e8d0>}\n\n    @wraps(func)\n    def patched(*args, **keywargs):\n>       with self.decoration_helper(patched,\n                                    args,\n                                    keywargs) as (newargs, newkeywargs):\n\n/usr/lib/python3.12/unittest/mock.py:1387: \n_ _ _ _ _ _ _ _ _ _ _ _ _ _ _ _ _ _ _ _ _ _ _ _ _ _ _ _ _ _ _ _ _ _ _ _ _ _ _ _ \n/usr/lib/python3.12/contextlib.py:137: in __enter__\n    return next(self.gen)\n/usr/lib/python3.12/unittest/mock.py:1369: in decoration_helper\n    arg = exit_stack.enter_context(patching)\n/usr/lib/python3.12/contextlib.py:526: in enter_context\n    result = _enter(cm)\n/usr/lib/python3.12/unittest/mock.py:1458: in __enter__\n    original, local = self.get_original()\n_ _ _ _ _ _ _ _ _ _ _ _ _ _ _ _ _ _ _ _ _ _ _ _ _ _ _ _ _ _ _ _ _ _ _ _ _ _ _ _ \n\nself = <unittest.mock._patch object at 0x7715d401bbc0>\n\n    def get_original(self):\n        target = self.getter()\n        name = self.attribute\n    \n        original = DEFAULT\n        local = False\n    \n        try:\n            original = target.__dict__[name]\n        except (AttributeError, KeyError):\n            original = getattr(target, name, DEFAULT)\n        else:\n            local = True\n    \n        if name in _builtins and isinstance(target, ModuleType):\n            self.create = True\n    \n        if not self.create and original is DEFAULT:\n>           raise AttributeError(\n                \"%s does not have the attribute %r\" % (target, name)\n            )\nE           AttributeError: <module '__main__' from '/home/jayasree/e-commerce/venv/bin/pytest'> does not have the attribute 'crud'\n\n/usr/lib/python3.12/unittest/mock.py:1431: AttributeError"}, "teardown": {"duration": 0.00019472799976938404, "outcome": "passed"}}, {"nodeid": "test_failed1.py::test_create_user_empty_email", "lineno": 251, "outcome": "failed", "keywords": ["test_create_user_empty_email", "__wrapped__", "patchings", "test_failed1.py", "backend"], "setup": {"duration": 0.00015364200226031244, "outcome": "passed"}, "call": {"duration": 0.00013149099686415866, "outcome": "failed", "crash": {"path": "/usr/lib/python3.12/unittest/mock.py", "lineno": 1431, "message": "AttributeError: <module '__main__' from '/home/jayasree/e-commerce/venv/bin/pytest'> does not have the attribute 'crud'"}, "traceback": [{"path": "/usr/lib/python3.12/unittest/mock.py", "lineno": 1387, "message": ""}, {"path": "/usr/lib/python3.12/contextlib.py", "lineno": 137, "message": "in __enter__"}, {"path": "/usr/lib/python3.12/unittest/mock.py", "lineno": 1369, "message": "in decoration_helper"}, {"path": "/usr/lib/python3.12/contextlib.py", "lineno": 526, "message": "in enter_context"}, {"path": "/usr/lib/python3.12/unittest/mock.py", "lineno": 1458, "message": "in __enter__"}, {"path": "/usr/lib/python3.12/unittest/mock.py", "lineno": 1431, "message": "AttributeError"}], "longrepr": "args = ()\nkeywargs = {'mock_db_session': <test_failed1.MockDBSession object at 0x7715d3f7c4d0>}\n\n    @wraps(func)\n    def patched(*args, **keywargs):\n>       with self.decoration_helper(patched,\n                                    args,\n                                    keywargs) as (newargs, newkeywargs):\n\n/usr/lib/python3.12/unittest/mock.py:1387: \n_ _ _ _ _ _ _ _ _ _ _ _ _ _ _ _ _ _ _ _ _ _ _ _ _ _ _ _ _ _ _ _ _ _ _ _ _ _ _ _ \n/usr/lib/python3.12/contextlib.py:137: in __enter__\n    return next(self.gen)\n/usr/lib/python3.12/unittest/mock.py:1369: in decoration_helper\n    arg = exit_stack.enter_context(patching)\n/usr/lib/python3.12/contextlib.py:526: in enter_context\n    result = _enter(cm)\n/usr/lib/python3.12/unittest/mock.py:1458: in __enter__\n    original, local = self.get_original()\n_ _ _ _ _ _ _ _ _ _ _ _ _ _ _ _ _ _ _ _ _ _ _ _ _ _ _ _ _ _ _ _ _ _ _ _ _ _ _ _ \n\nself = <unittest.mock._patch object at 0x7715d401bd40>\n\n    def get_original(self):\n        target = self.getter()\n        name = self.attribute\n    \n        original = DEFAULT\n        local = False\n    \n        try:\n            original = target.__dict__[name]\n        except (AttributeError, KeyError):\n            original = getattr(target, name, DEFAULT)\n        else:\n            local = True\n    \n        if name in _builtins and isinstance(target, ModuleType):\n            self.create = True\n    \n        if not self.create and original is DEFAULT:\n>           raise AttributeError(\n                \"%s does not have the attribute %r\" % (target, name)\n            )\nE           AttributeError: <module '__main__' from '/home/jayasree/e-commerce/venv/bin/pytest'> does not have the attribute 'crud'\n\n/usr/lib/python3.12/unittest/mock.py:1431: AttributeError"}, "teardown": {"duration": 0.0001825500003178604, "outcome": "passed"}}, {"nodeid": "test_failed1.py::test_create_user_invalid_user_in_data", "lineno": 287, "outcome": "failed", "keywords": ["test_create_user_invalid_user_in_data", "__wrapped__", "patchings", "test_failed1.py", "backend"], "setup": {"duration": 0.00020538300304906443, "outcome": "passed"}, "call": {"duration": 0.00014595899847336113, "outcome": "failed", "crash": {"path": "/usr/lib/python3.12/unittest/mock.py", "lineno": 1431, "message": "AttributeError: <module '__main__' from '/home/jayasree/e-commerce/venv/bin/pytest'> does not have the attribute 'crud'"}, "traceback": [{"path": "/usr/lib/python3.12/unittest/mock.py", "lineno": 1387, "message": ""}, {"path": "/usr/lib/python3.12/contextlib.py", "lineno": 137, "message": "in __enter__"}, {"path": "/usr/lib/python3.12/unittest/mock.py", "lineno": 1369, "message": "in decoration_helper"}, {"path": "/usr/lib/python3.12/contextlib.py", "lineno": 526, "message": "in enter_context"}, {"path": "/usr/lib/python3.12/unittest/mock.py", "lineno": 1458, "message": "in __enter__"}, {"path": "/usr/lib/python3.12/unittest/mock.py", "lineno": 1431, "message": "AttributeError"}], "longrepr": "args = ()\nkeywargs = {'mock_db_session': <test_failed1.MockDBSession object at 0x7715d3f7d430>}\n\n    @wraps(func)\n    def patched(*args, **keywargs):\n>       with self.decoration_helper(patched,\n                                    args,\n                                    keywargs) as (newargs, newkeywargs):\n\n/usr/lib/python3.12/unittest/mock.py:1387: \n_ _ _ _ _ _ _ _ _ _ _ _ _ _ _ _ _ _ _ _ _ _ _ _ _ _ _ _ _ _ _ _ _ _ _ _ _ _ _ _ \n/usr/lib/python3.12/contextlib.py:137: in __enter__\n    return next(self.gen)\n/usr/lib/python3.12/unittest/mock.py:1369: in decoration_helper\n    arg = exit_stack.enter_context(patching)\n/usr/lib/python3.12/contextlib.py:526: in enter_context\n    result = _enter(cm)\n/usr/lib/python3.12/unittest/mock.py:1458: in __enter__\n    original, local = self.get_original()\n_ _ _ _ _ _ _ _ _ _ _ _ _ _ _ _ _ _ _ _ _ _ _ _ _ _ _ _ _ _ _ _ _ _ _ _ _ _ _ _ \n\nself = <unittest.mock._patch object at 0x7715d401bec0>\n\n    def get_original(self):\n        target = self.getter()\n        name = self.attribute\n    \n        original = DEFAULT\n        local = False\n    \n        try:\n            original = target.__dict__[name]\n        except (AttributeError, KeyError):\n            original = getattr(target, name, DEFAULT)\n        else:\n            local = True\n    \n        if name in _builtins and isinstance(target, ModuleType):\n            self.create = True\n    \n        if not self.create and original is DEFAULT:\n>           raise AttributeError(\n                \"%s does not have the attribute %r\" % (target, name)\n            )\nE           AttributeError: <module '__main__' from '/home/jayasree/e-commerce/venv/bin/pytest'> does not have the attribute 'crud'\n\n/usr/lib/python3.12/unittest/mock.py:1431: AttributeError"}, "teardown": {"duration": 0.00023281199901248328, "outcome": "passed"}}, {"nodeid": "test_failed1.py::test_create_user_whitespace_email", "lineno": 321, "outcome": "failed", "keywords": ["test_create_user_whitespace_email", "__wrapped__", "patchings", "test_failed1.py", "backend"], "setup": {"duration": 0.00021901799846091308, "outcome": "passed"}, "call": {"duration": 0.0002530720012146048, "outcome": "failed", "crash": {"path": "/usr/lib/python3.12/unittest/mock.py", "lineno": 1431, "message": "AttributeError: <module '__main__' from '/home/jayasree/e-commerce/venv/bin/pytest'> does not have the attribute 'crud'"}, "traceback": [{"path": "/usr/lib/python3.12/unittest/mock.py", "lineno": 1387, "message": ""}, {"path": "/usr/lib/python3.12/contextlib.py", "lineno": 137, "message": "in __enter__"}, {"path": "/usr/lib/python3.12/unittest/mock.py", "lineno": 1369, "message": "in decoration_helper"}, {"path": "/usr/lib/python3.12/contextlib.py", "lineno": 526, "message": "in enter_context"}, {"path": "/usr/lib/python3.12/unittest/mock.py", "lineno": 1458, "message": "in __enter__"}, {"path": "/usr/lib/python3.12/unittest/mock.py", "lineno": 1431, "message": "AttributeError"}], "longrepr": "args = ()\nkeywargs = {'mock_db_session': <test_failed1.MockDBSession object at 0x7715d3f7e1b0>}\n\n    @wraps(func)\n    def patched(*args, **keywargs):\n>       with self.decoration_helper(patched,\n                                    args,\n                                    keywargs) as (newargs, newkeywargs):\n\n/usr/lib/python3.12/unittest/mock.py:1387: \n_ _ _ _ _ _ _ _ _ _ _ _ _ _ _ _ _ _ _ _ _ _ _ _ _ _ _ _ _ _ _ _ _ _ _ _ _ _ _ _ \n/usr/lib/python3.12/contextlib.py:137: in __enter__\n    return next(self.gen)\n/usr/lib/python3.12/unittest/mock.py:1369: in decoration_helper\n    arg = exit_stack.enter_context(patching)\n/usr/lib/python3.12/contextlib.py:526: in enter_context\n    result = _enter(cm)\n/usr/lib/python3.12/unittest/mock.py:1458: in __enter__\n    original, local = self.get_original()\n_ _ _ _ _ _ _ _ _ _ _ _ _ _ _ _ _ _ _ _ _ _ _ _ _ _ _ _ _ _ _ _ _ _ _ _ _ _ _ _ \n\nself = <unittest.mock._patch object at 0x7715d402c080>\n\n    def get_original(self):\n        target = self.getter()\n        name = self.attribute\n    \n        original = DEFAULT\n        local = False\n    \n        try:\n            original = target.__dict__[name]\n        except (AttributeError, KeyError):\n            original = getattr(target, name, DEFAULT)\n        else:\n            local = True\n    \n        if name in _builtins and isinstance(target, ModuleType):\n            self.create = True\n    \n        if not self.create and original is DEFAULT:\n>           raise AttributeError(\n                \"%s does not have the attribute %r\" % (target, name)\n            )\nE           AttributeError: <module '__main__' from '/home/jayasree/e-commerce/venv/bin/pytest'> does not have the attribute 'crud'\n\n/usr/lib/python3.12/unittest/mock.py:1431: AttributeError"}, "teardown": {"duration": 0.000181764000444673, "outcome": "passed"}}, {"nodeid": "test_failed1.py::test_create_user_emails_disabled", "lineno": 357, "outcome": "failed", "keywords": ["test_create_user_emails_disabled", "__wrapped__", "patchings", "test_failed1.py", "backend"], "setup": {"duration": 0.00014135600213194266, "outcome": "passed"}, "call": {"duration": 0.00013079700147500262, "outcome": "failed", "crash": {"path": "/usr/lib/python3.12/unittest/mock.py", "lineno": 1431, "message": "AttributeError: <module '__main__' from '/home/jayasree/e-commerce/venv/bin/pytest'> does not have the attribute 'crud'"}, "traceback": [{"path": "/usr/lib/python3.12/unittest/mock.py", "lineno": 1387, "message": ""}, {"path": "/usr/lib/python3.12/contextlib.py", "lineno": 137, "message": "in __enter__"}, {"path": "/usr/lib/python3.12/unittest/mock.py", "lineno": 1369, "message": "in decoration_helper"}, {"path": "/usr/lib/python3.12/contextlib.py", "lineno": 526, "message": "in enter_context"}, {"path": "/usr/lib/python3.12/unittest/mock.py", "lineno": 1458, "message": "in __enter__"}, {"path": "/usr/lib/python3.12/unittest/mock.py", "lineno": 1431, "message": "AttributeError"}], "longrepr": "args = ()\nkeywargs = {'mock_db_session': <test_failed1.MockDBSession object at 0x7715d402fc20>}\n\n    @wraps(func)\n    def patched(*args, **keywargs):\n>       with self.decoration_helper(patched,\n                                    args,\n                                    keywargs) as (newargs, newkeywargs):\n\n/usr/lib/python3.12/unittest/mock.py:1387: \n_ _ _ _ _ _ _ _ _ _ _ _ _ _ _ _ _ _ _ _ _ _ _ _ _ _ _ _ _ _ _ _ _ _ _ _ _ _ _ _ \n/usr/lib/python3.12/contextlib.py:137: in __enter__\n    return next(self.gen)\n/usr/lib/python3.12/unittest/mock.py:1369: in decoration_helper\n    arg = exit_stack.enter_context(patching)\n/usr/lib/python3.12/contextlib.py:526: in enter_context\n    result = _enter(cm)\n/usr/lib/python3.12/unittest/mock.py:1458: in __enter__\n    original, local = self.get_original()\n_ _ _ _ _ _ _ _ _ _ _ _ _ _ _ _ _ _ _ _ _ _ _ _ _ _ _ _ _ _ _ _ _ _ _ _ _ _ _ _ \n\nself = <unittest.mock._patch object at 0x7715d402c200>\n\n    def get_original(self):\n        target = self.getter()\n        name = self.attribute\n    \n        original = DEFAULT\n        local = False\n    \n        try:\n            original = target.__dict__[name]\n        except (AttributeError, KeyError):\n            original = getattr(target, name, DEFAULT)\n        else:\n            local = True\n    \n        if name in _builtins and isinstance(target, ModuleType):\n            self.create = True\n    \n        if not self.create and original is DEFAULT:\n>           raise AttributeError(\n                \"%s does not have the attribute %r\" % (target, name)\n            )\nE           AttributeError: <module '__main__' from '/home/jayasree/e-commerce/venv/bin/pytest'> does not have the attribute 'crud'\n\n/usr/lib/python3.12/unittest/mock.py:1431: AttributeError"}, "teardown": {"duration": 0.00045361099910223857, "outcome": "passed"}}, {"nodeid": "test_failed1.py::test_create_user_crud_create_user_raises_exception", "lineno": 392, "outcome": "failed", "keywords": ["test_create_user_crud_create_user_raises_exception", "__wrapped__", "patchings", "test_failed1.py", "backend"], "setup": {"duration": 0.0003635520006355364, "outcome": "passed"}, "call": {"duration": 0.00030836800215183757, "outcome": "failed", "crash": {"path": "/usr/lib/python3.12/unittest/mock.py", "lineno": 1431, "message": "AttributeError: <module '__main__' from '/home/jayasree/e-commerce/venv/bin/pytest'> does not have the attribute 'crud'"}, "traceback": [{"path": "/usr/lib/python3.12/unittest/mock.py", "lineno": 1387, "message": ""}, {"path": "/usr/lib/python3.12/contextlib.py", "lineno": 137, "message": "in __enter__"}, {"path": "/usr/lib/python3.12/unittest/mock.py", "lineno": 1369, "message": "in decoration_helper"}, {"path": "/usr/lib/python3.12/contextlib.py", "lineno": 526, "message": "in enter_context"}, {"path": "/usr/lib/python3.12/unittest/mock.py", "lineno": 1458, "message": "in __enter__"}, {"path": "/usr/lib/python3.12/unittest/mock.py", "lineno": 1431, "message": "AttributeError"}], "longrepr": "args = ()\nkeywargs = {'mock_db_session': <test_failed1.MockDBSession object at 0x7715d3f7e390>}\n\n    @wraps(func)\n    def patched(*args, **keywargs):\n>       with self.decoration_helper(patched,\n                                    args,\n                                    keywargs) as (newargs, newkeywargs):\n\n/usr/lib/python3.12/unittest/mock.py:1387: \n_ _ _ _ _ _ _ _ _ _ _ _ _ _ _ _ _ _ _ _ _ _ _ _ _ _ _ _ _ _ _ _ _ _ _ _ _ _ _ _ \n/usr/lib/python3.12/contextlib.py:137: in __enter__\n    return next(self.gen)\n/usr/lib/python3.12/unittest/mock.py:1369: in decoration_helper\n    arg = exit_stack.enter_context(patching)\n/usr/lib/python3.12/contextlib.py:526: in enter_context\n    result = _enter(cm)\n/usr/lib/python3.12/unittest/mock.py:1458: in __enter__\n    original, local = self.get_original()\n_ _ _ _ _ _ _ _ _ _ _ _ _ _ _ _ _ _ _ _ _ _ _ _ _ _ _ _ _ _ _ _ _ _ _ _ _ _ _ _ \n\nself = <unittest.mock._patch object at 0x7715d402c380>\n\n    def get_original(self):\n        target = self.getter()\n        name = self.attribute\n    \n        original = DEFAULT\n        local = False\n    \n        try:\n            original = target.__dict__[name]\n        except (AttributeError, KeyError):\n            original = getattr(target, name, DEFAULT)\n        else:\n            local = True\n    \n        if name in _builtins and isinstance(target, ModuleType):\n            self.create = True\n    \n        if not self.create and original is DEFAULT:\n>           raise AttributeError(\n                \"%s does not have the attribute %r\" % (target, name)\n            )\nE           AttributeError: <module '__main__' from '/home/jayasree/e-commerce/venv/bin/pytest'> does not have the attribute 'crud'\n\n/usr/lib/python3.12/unittest/mock.py:1431: AttributeError"}, "teardown": {"duration": 0.00018680200082599185, "outcome": "passed"}}, {"nodeid": "test_failed1.py::test_create_user_email_is_none", "lineno": 424, "outcome": "failed", "keywords": ["test_create_user_email_is_none", "__wrapped__", "patchings", "test_failed1.py", "backend"], "setup": {"duration": 0.000146112000948051, "outcome": "passed"}, "call": {"duration": 0.00013346199921215884, "outcome": "failed", "crash": {"path": "/usr/lib/python3.12/unittest/mock.py", "lineno": 1431, "message": "AttributeError: <module '__main__' from '/home/jayasree/e-commerce/venv/bin/pytest'> does not have the attribute 'crud'"}, "traceback": [{"path": "/usr/lib/python3.12/unittest/mock.py", "lineno": 1387, "message": ""}, {"path": "/usr/lib/python3.12/contextlib.py", "lineno": 137, "message": "in __enter__"}, {"path": "/usr/lib/python3.12/unittest/mock.py", "lineno": 1369, "message": "in decoration_helper"}, {"path": "/usr/lib/python3.12/contextlib.py", "lineno": 526, "message": "in enter_context"}, {"path": "/usr/lib/python3.12/unittest/mock.py", "lineno": 1458, "message": "in __enter__"}, {"path": "/usr/lib/python3.12/unittest/mock.py", "lineno": 1431, "message": "AttributeError"}], "longrepr": "args = ()\nkeywargs = {'mock_db_session': <test_failed1.MockDBSession object at 0x7715d3f7d7f0>}\n\n    @wraps(func)\n    def patched(*args, **keywargs):\n>       with self.decoration_helper(patched,\n                                    args,\n                                    keywargs) as (newargs, newkeywargs):\n\n/usr/lib/python3.12/unittest/mock.py:1387: \n_ _ _ _ _ _ _ _ _ _ _ _ _ _ _ _ _ _ _ _ _ _ _ _ _ _ _ _ _ _ _ _ _ _ _ _ _ _ _ _ \n/usr/lib/python3.12/contextlib.py:137: in __enter__\n    return next(self.gen)\n/usr/lib/python3.12/unittest/mock.py:1369: in decoration_helper\n    arg = exit_stack.enter_context(patching)\n/usr/lib/python3.12/contextlib.py:526: in enter_context\n    result = _enter(cm)\n/usr/lib/python3.12/unittest/mock.py:1458: in __enter__\n    original, local = self.get_original()\n_ _ _ _ _ _ _ _ _ _ _ _ _ _ _ _ _ _ _ _ _ _ _ _ _ _ _ _ _ _ _ _ _ _ _ _ _ _ _ _ \n\nself = <unittest.mock._patch object at 0x7715d402c500>\n\n    def get_original(self):\n        target = self.getter()\n        name = self.attribute\n    \n        original = DEFAULT\n        local = False\n    \n        try:\n            original = target.__dict__[name]\n        except (AttributeError, KeyError):\n            original = getattr(target, name, DEFAULT)\n        else:\n            local = True\n    \n        if name in _builtins and isinstance(target, ModuleType):\n            self.create = True\n    \n        if not self.create and original is DEFAULT:\n>           raise AttributeError(\n                \"%s does not have the attribute %r\" % (target, name)\n            )\nE           AttributeError: <module '__main__' from '/home/jayasree/e-commerce/venv/bin/pytest'> does not have the attribute 'crud'\n\n/usr/lib/python3.12/unittest/mock.py:1431: AttributeError"}, "teardown": {"duration": 0.0001748590002534911, "outcome": "passed"}}, {"nodeid": "test_failed1.py::test_create_user_generate_new_account_email_raises", "lineno": 459, "outcome": "failed", "keywords": ["test_create_user_generate_new_account_email_raises", "__wrapped__", "patchings", "test_failed1.py", "backend"], "setup": {"duration": 0.00013793600010103546, "outcome": "passed"}, "call": {"duration": 0.0001316640009463299, "outcome": "failed", "crash": {"path": "/usr/lib/python3.12/unittest/mock.py", "lineno": 1431, "message": "AttributeError: <module '__main__' from '/home/jayasree/e-commerce/venv/bin/pytest'> does not have the attribute 'crud'"}, "traceback": [{"path": "/usr/lib/python3.12/unittest/mock.py", "lineno": 1387, "message": ""}, {"path": "/usr/lib/python3.12/contextlib.py", "lineno": 137, "message": "in __enter__"}, {"path": "/usr/lib/python3.12/unittest/mock.py", "lineno": 1369, "message": "in decoration_helper"}, {"path": "/usr/lib/python3.12/contextlib.py", "lineno": 526, "message": "in enter_context"}, {"path": "/usr/lib/python3.12/unittest/mock.py", "lineno": 1458, "message": "in __enter__"}, {"path": "/usr/lib/python3.12/unittest/mock.py", "lineno": 1431, "message": "AttributeError"}], "longrepr": "args = ()\nkeywargs = {'mock_db_session': <test_failed1.MockDBSession object at 0x7715d3f7fb30>}\n\n    @wraps(func)\n    def patched(*args, **keywargs):\n>       with self.decoration_helper(patched,\n                                    args,\n                                    keywargs) as (newargs, newkeywargs):\n\n/usr/lib/python3.12/unittest/mock.py:1387: \n_ _ _ _ _ _ _ _ _ _ _ _ _ _ _ _ _ _ _ _ _ _ _ _ _ _ _ _ _ _ _ _ _ _ _ _ _ _ _ _ \n/usr/lib/python3.12/contextlib.py:137: in __enter__\n    return next(self.gen)\n/usr/lib/python3.12/unittest/mock.py:1369: in decoration_helper\n    arg = exit_stack.enter_context(patching)\n/usr/lib/python3.12/contextlib.py:526: in enter_context\n    result = _enter(cm)\n/usr/lib/python3.12/unittest/mock.py:1458: in __enter__\n    original, local = self.get_original()\n_ _ _ _ _ _ _ _ _ _ _ _ _ _ _ _ _ _ _ _ _ _ _ _ _ _ _ _ _ _ _ _ _ _ _ _ _ _ _ _ \n\nself = <unittest.mock._patch object at 0x7715d402c680>\n\n    def get_original(self):\n        target = self.getter()\n        name = self.attribute\n    \n        original = DEFAULT\n        local = False\n    \n        try:\n            original = target.__dict__[name]\n        except (AttributeError, KeyError):\n            original = getattr(target, name, DEFAULT)\n        else:\n            local = True\n    \n        if name in _builtins and isinstance(target, ModuleType):\n            self.create = True\n    \n        if not self.create and original is DEFAULT:\n>           raise AttributeError(\n                \"%s does not have the attribute %r\" % (target, name)\n            )\nE           AttributeError: <module '__main__' from '/home/jayasree/e-commerce/venv/bin/pytest'> does not have the attribute 'crud'\n\n/usr/lib/python3.12/unittest/mock.py:1431: AttributeError"}, "teardown": {"duration": 0.00017816100080381148, "outcome": "passed"}}, {"nodeid": "test_failed1.py::test_create_user_send_email_raises", "lineno": 494, "outcome": "failed", "keywords": ["test_create_user_send_email_raises", "__wrapped__", "patchings", "test_failed1.py", "backend"], "setup": {"duration": 0.00014672900215373375, "outcome": "passed"}, "call": {"duration": 0.00014802199802943505, "outcome": "failed", "crash": {"path": "/usr/lib/python3.12/unittest/mock.py", "lineno": 1431, "message": "AttributeError: <module '__main__' from '/home/jayasree/e-commerce/venv/bin/pytest'> does not have the attribute 'crud'"}, "traceback": [{"path": "/usr/lib/python3.12/unittest/mock.py", "lineno": 1387, "message": ""}, {"path": "/usr/lib/python3.12/contextlib.py", "lineno": 137, "message": "in __enter__"}, {"path": "/usr/lib/python3.12/unittest/mock.py", "lineno": 1369, "message": "in decoration_helper"}, {"path": "/usr/lib/python3.12/contextlib.py", "lineno": 526, "message": "in enter_context"}, {"path": "/usr/lib/python3.12/unittest/mock.py", "lineno": 1458, "message": "in __enter__"}, {"path": "/usr/lib/python3.12/unittest/mock.py", "lineno": 1431, "message": "AttributeError"}], "longrepr": "args = ()\nkeywargs = {'mock_db_session': <test_failed1.MockDBSession object at 0x7715d3e9cbc0>}\n\n    @wraps(func)\n    def patched(*args, **keywargs):\n>       with self.decoration_helper(patched,\n                                    args,\n                                    keywargs) as (newargs, newkeywargs):\n\n/usr/lib/python3.12/unittest/mock.py:1387: \n_ _ _ _ _ _ _ _ _ _ _ _ _ _ _ _ _ _ _ _ _ _ _ _ _ _ _ _ _ _ _ _ _ _ _ _ _ _ _ _ \n/usr/lib/python3.12/contextlib.py:137: in __enter__\n    return next(self.gen)\n/usr/lib/python3.12/unittest/mock.py:1369: in decoration_helper\n    arg = exit_stack.enter_context(patching)\n/usr/lib/python3.12/contextlib.py:526: in enter_context\n    result = _enter(cm)\n/usr/lib/python3.12/unittest/mock.py:1458: in __enter__\n    original, local = self.get_original()\n_ _ _ _ _ _ _ _ _ _ _ _ _ _ _ _ _ _ _ _ _ _ _ _ _ _ _ _ _ _ _ _ _ _ _ _ _ _ _ _ \n\nself = <unittest.mock._patch object at 0x7715d402c8c0>\n\n    def get_original(self):\n        target = self.getter()\n        name = self.attribute\n    \n        original = DEFAULT\n        local = False\n    \n        try:\n            original = target.__dict__[name]\n        except (AttributeError, KeyError):\n            original = getattr(target, name, DEFAULT)\n        else:\n            local = True\n    \n        if name in _builtins and isinstance(target, ModuleType):\n            self.create = True\n    \n        if not self.create and original is DEFAULT:\n>           raise AttributeError(\n                \"%s does not have the attribute %r\" % (target, name)\n            )\nE           AttributeError: <module '__main__' from '/home/jayasree/e-commerce/venv/bin/pytest'> does not have the attribute 'crud'\n\n/usr/lib/python3.12/unittest/mock.py:1431: AttributeError"}, "teardown": {"duration": 0.000260160999459913, "outcome": "passed"}}, {"nodeid": "test_failed1.py::test_send_email_positive_case", "lineno": 533, "outcome": "failed", "keywords": ["test_send_email_positive_case", "__wrapped__", "patchings", "test_failed1.py", "backend"], "setup": {"duration": 0.00012564599819597788, "outcome": "passed"}, "call": {"duration": 0.0001795390016923193, "outcome": "failed", "crash": {"path": "/usr/lib/python3.12/unittest/mock.py", "lineno": 1431, "message": "AttributeError: <module '__main__' from '/home/jayasree/e-commerce/venv/bin/pytest'> does not have the attribute 'settings'"}, "traceback": [{"path": "/usr/lib/python3.12/unittest/mock.py", "lineno": 1387, "message": ""}, {"path": "/usr/lib/python3.12/contextlib.py", "lineno": 137, "message": "in __enter__"}, {"path": "/usr/lib/python3.12/unittest/mock.py", "lineno": 1369, "message": "in decoration_helper"}, {"path": "/usr/lib/python3.12/contextlib.py", "lineno": 526, "message": "in enter_context"}, {"path": "/usr/lib/python3.12/unittest/mock.py", "lineno": 1458, "message": "in __enter__"}, {"path": "/usr/lib/python3.12/unittest/mock.py", "lineno": 1431, "message": "AttributeError"}], "longrepr": "args = (), keywargs = {}\n\n    @wraps(func)\n    def patched(*args, **keywargs):\n>       with self.decoration_helper(patched,\n                                    args,\n                                    keywargs) as (newargs, newkeywargs):\n\n/usr/lib/python3.12/unittest/mock.py:1387: \n_ _ _ _ _ _ _ _ _ _ _ _ _ _ _ _ _ _ _ _ _ _ _ _ _ _ _ _ _ _ _ _ _ _ _ _ _ _ _ _ \n/usr/lib/python3.12/contextlib.py:137: in __enter__\n    return next(self.gen)\n/usr/lib/python3.12/unittest/mock.py:1369: in decoration_helper\n    arg = exit_stack.enter_context(patching)\n/usr/lib/python3.12/contextlib.py:526: in enter_context\n    result = _enter(cm)\n/usr/lib/python3.12/unittest/mock.py:1458: in __enter__\n    original, local = self.get_original()\n_ _ _ _ _ _ _ _ _ _ _ _ _ _ _ _ _ _ _ _ _ _ _ _ _ _ _ _ _ _ _ _ _ _ _ _ _ _ _ _ \n\nself = <unittest.mock._patch object at 0x7715d402c9e0>\n\n    def get_original(self):\n        target = self.getter()\n        name = self.attribute\n    \n        original = DEFAULT\n        local = False\n    \n        try:\n            original = target.__dict__[name]\n        except (AttributeError, KeyError):\n            original = getattr(target, name, DEFAULT)\n        else:\n            local = True\n    \n        if name in _builtins and isinstance(target, ModuleType):\n            self.create = True\n    \n        if not self.create and original is DEFAULT:\n>           raise AttributeError(\n                \"%s does not have the attribute %r\" % (target, name)\n            )\nE           AttributeError: <module '__main__' from '/home/jayasree/e-commerce/venv/bin/pytest'> does not have the attribute 'settings'\n\n/usr/lib/python3.12/unittest/mock.py:1431: AttributeError"}, "teardown": {"duration": 0.0008002669965208042, "outcome": "passed"}}, {"nodeid": "test_failed1.py::test_send_email_emails_disabled", "lineno": 577, "outcome": "failed", "keywords": ["test_send_email_emails_disabled", "__wrapped__", "patchings", "test_failed1.py", "backend"], "setup": {"duration": 0.0002872039985959418, "outcome": "passed"}, "call": {"duration": 0.00015133900160435587, "outcome": "failed", "crash": {"path": "/usr/lib/python3.12/unittest/mock.py", "lineno": 1431, "message": "AttributeError: <module '__main__' from '/home/jayasree/e-commerce/venv/bin/pytest'> does not have the attribute 'settings'"}, "traceback": [{"path": "/usr/lib/python3.12/unittest/mock.py", "lineno": 1387, "message": ""}, {"path": "/usr/lib/python3.12/contextlib.py", "lineno": 137, "message": "in __enter__"}, {"path": "/usr/lib/python3.12/unittest/mock.py", "lineno": 1369, "message": "in decoration_helper"}, {"path": "/usr/lib/python3.12/contextlib.py", "lineno": 526, "message": "in enter_context"}, {"path": "/usr/lib/python3.12/unittest/mock.py", "lineno": 1458, "message": "in __enter__"}, {"path": "/usr/lib/python3.12/unittest/mock.py", "lineno": 1431, "message": "AttributeError"}], "longrepr": "args = (), keywargs = {}\n\n    @wraps(func)\n    def patched(*args, **keywargs):\n>       with self.decoration_helper(patched,\n                                    args,\n                                    keywargs) as (newargs, newkeywargs):\n\n/usr/lib/python3.12/unittest/mock.py:1387: \n_ _ _ _ _ _ _ _ _ _ _ _ _ _ _ _ _ _ _ _ _ _ _ _ _ _ _ _ _ _ _ _ _ _ _ _ _ _ _ _ \n/usr/lib/python3.12/contextlib.py:137: in __enter__\n    return next(self.gen)\n/usr/lib/python3.12/unittest/mock.py:1369: in decoration_helper\n    arg = exit_stack.enter_context(patching)\n/usr/lib/python3.12/contextlib.py:526: in enter_context\n    result = _enter(cm)\n/usr/lib/python3.12/unittest/mock.py:1458: in __enter__\n    original, local = self.get_original()\n_ _ _ _ _ _ _ _ _ _ _ _ _ _ _ _ _ _ _ _ _ _ _ _ _ _ _ _ _ _ _ _ _ _ _ _ _ _ _ _ \n\nself = <unittest.mock._patch object at 0x7715d402cb60>\n\n    def get_original(self):\n        target = self.getter()\n        name = self.attribute\n    \n        original = DEFAULT\n        local = False\n    \n        try:\n            original = target.__dict__[name]\n        except (AttributeError, KeyError):\n            original = getattr(target, name, DEFAULT)\n        else:\n            local = True\n    \n        if name in _builtins and isinstance(target, ModuleType):\n            self.create = True\n    \n        if not self.create and original is DEFAULT:\n>           raise AttributeError(\n                \"%s does not have the attribute %r\" % (target, name)\n            )\nE           AttributeError: <module '__main__' from '/home/jayasree/e-commerce/venv/bin/pytest'> does not have the attribute 'settings'\n\n/usr/lib/python3.12/unittest/mock.py:1431: AttributeError"}, "teardown": {"duration": 0.000698085998010356, "outcome": "passed"}}, {"nodeid": "test_failed1.py::test_send_email_empty_email_to", "lineno": 601, "outcome": "failed", "keywords": ["test_send_email_empty_email_to", "__wrapped__", "patchings", "test_failed1.py", "backend"], "setup": {"duration": 0.00020677999782492407, "outcome": "passed"}, "call": {"duration": 0.00017609999849810265, "outcome": "failed", "crash": {"path": "/usr/lib/python3.12/unittest/mock.py", "lineno": 1431, "message": "AttributeError: <module '__main__' from '/home/jayasree/e-commerce/venv/bin/pytest'> does not have the attribute 'settings'"}, "traceback": [{"path": "/usr/lib/python3.12/unittest/mock.py", "lineno": 1387, "message": ""}, {"path": "/usr/lib/python3.12/contextlib.py", "lineno": 137, "message": "in __enter__"}, {"path": "/usr/lib/python3.12/unittest/mock.py", "lineno": 1369, "message": "in decoration_helper"}, {"path": "/usr/lib/python3.12/contextlib.py", "lineno": 526, "message": "in enter_context"}, {"path": "/usr/lib/python3.12/unittest/mock.py", "lineno": 1458, "message": "in __enter__"}, {"path": "/usr/lib/python3.12/unittest/mock.py", "lineno": 1431, "message": "AttributeError"}], "longrepr": "args = (), keywargs = {}\n\n    @wraps(func)\n    def patched(*args, **keywargs):\n>       with self.decoration_helper(patched,\n                                    args,\n                                    keywargs) as (newargs, newkeywargs):\n\n/usr/lib/python3.12/unittest/mock.py:1387: \n_ _ _ _ _ _ _ _ _ _ _ _ _ _ _ _ _ _ _ _ _ _ _ _ _ _ _ _ _ _ _ _ _ _ _ _ _ _ _ _ \n/usr/lib/python3.12/contextlib.py:137: in __enter__\n    return next(self.gen)\n/usr/lib/python3.12/unittest/mock.py:1369: in decoration_helper\n    arg = exit_stack.enter_context(patching)\n/usr/lib/python3.12/contextlib.py:526: in enter_context\n    result = _enter(cm)\n/usr/lib/python3.12/unittest/mock.py:1458: in __enter__\n    original, local = self.get_original()\n_ _ _ _ _ _ _ _ _ _ _ _ _ _ _ _ _ _ _ _ _ _ _ _ _ _ _ _ _ _ _ _ _ _ _ _ _ _ _ _ \n\nself = <unittest.mock._patch object at 0x7715d402cce0>\n\n    def get_original(self):\n        target = self.getter()\n        name = self.attribute\n    \n        original = DEFAULT\n        local = False\n    \n        try:\n            original = target.__dict__[name]\n        except (AttributeError, KeyError):\n            original = getattr(target, name, DEFAULT)\n        else:\n            local = True\n    \n        if name in _builtins and isinstance(target, ModuleType):\n            self.create = True\n    \n        if not self.create and original is DEFAULT:\n>           raise AttributeError(\n                \"%s does not have the attribute %r\" % (target, name)\n            )\nE           AttributeError: <module '__main__' from '/home/jayasree/e-commerce/venv/bin/pytest'> does not have the attribute 'settings'\n\n/usr/lib/python3.12/unittest/mock.py:1431: AttributeError"}, "teardown": {"duration": 0.0001755599987518508, "outcome": "passed"}}, {"nodeid": "test_failed1.py::test_send_email_empty_subject_and_html_content", "lineno": 645, "outcome": "failed", "keywords": ["test_send_email_empty_subject_and_html_content", "__wrapped__", "patchings", "test_failed1.py", "backend"], "setup": {"duration": 8.42769986775238e-05, "outcome": "passed"}, "call": {"duration": 0.00014477000149781816, "outcome": "failed", "crash": {"path": "/usr/lib/python3.12/unittest/mock.py", "lineno": 1431, "message": "AttributeError: <module '__main__' from '/home/jayasree/e-commerce/venv/bin/pytest'> does not have the attribute 'settings'"}, "traceback": [{"path": "/usr/lib/python3.12/unittest/mock.py", "lineno": 1387, "message": ""}, {"path": "/usr/lib/python3.12/contextlib.py", "lineno": 137, "message": "in __enter__"}, {"path": "/usr/lib/python3.12/unittest/mock.py", "lineno": 1369, "message": "in decoration_helper"}, {"path": "/usr/lib/python3.12/contextlib.py", "lineno": 526, "message": "in enter_context"}, {"path": "/usr/lib/python3.12/unittest/mock.py", "lineno": 1458, "message": "in __enter__"}, {"path": "/usr/lib/python3.12/unittest/mock.py", "lineno": 1431, "message": "AttributeError"}], "longrepr": "args = (), keywargs = {}\n\n    @wraps(func)\n    def patched(*args, **keywargs):\n>       with self.decoration_helper(patched,\n                                    args,\n                                    keywargs) as (newargs, newkeywargs):\n\n/usr/lib/python3.12/unittest/mock.py:1387: \n_ _ _ _ _ _ _ _ _ _ _ _ _ _ _ _ _ _ _ _ _ _ _ _ _ _ _ _ _ _ _ _ _ _ _ _ _ _ _ _ \n/usr/lib/python3.12/contextlib.py:137: in __enter__\n    return next(self.gen)\n/usr/lib/python3.12/unittest/mock.py:1369: in decoration_helper\n    arg = exit_stack.enter_context(patching)\n/usr/lib/python3.12/contextlib.py:526: in enter_context\n    result = _enter(cm)\n/usr/lib/python3.12/unittest/mock.py:1458: in __enter__\n    original, local = self.get_original()\n_ _ _ _ _ _ _ _ _ _ _ _ _ _ _ _ _ _ _ _ _ _ _ _ _ _ _ _ _ _ _ _ _ _ _ _ _ _ _ _ \n\nself = <unittest.mock._patch object at 0x7715d402ce60>\n\n    def get_original(self):\n        target = self.getter()\n        name = self.attribute\n    \n        original = DEFAULT\n        local = False\n    \n        try:\n            original = target.__dict__[name]\n        except (AttributeError, KeyError):\n            original = getattr(target, name, DEFAULT)\n        else:\n            local = True\n    \n        if name in _builtins and isinstance(target, ModuleType):\n            self.create = True\n    \n        if not self.create and original is DEFAULT:\n>           raise AttributeError(\n                \"%s does not have the attribute %r\" % (target, name)\n            )\nE           AttributeError: <module '__main__' from '/home/jayasree/e-commerce/venv/bin/pytest'> does not have the attribute 'settings'\n\n/usr/lib/python3.12/unittest/mock.py:1431: AttributeError"}, "teardown": {"duration": 0.00016077599866548553, "outcome": "passed"}}, {"nodeid": "test_failed1.py::test_send_email_invalid_email_address", "lineno": 689, "outcome": "failed", "keywords": ["test_send_email_invalid_email_address", "__wrapped__", "patchings", "test_failed1.py", "backend"], "setup": {"duration": 8.895099745132029e-05, "outcome": "passed"}, "call": {"duration": 0.0001311429987254087, "outcome": "failed", "crash": {"path": "/usr/lib/python3.12/unittest/mock.py", "lineno": 1431, "message": "AttributeError: <module '__main__' from '/home/jayasree/e-commerce/venv/bin/pytest'> does not have the attribute 'settings'"}, "traceback": [{"path": "/usr/lib/python3.12/unittest/mock.py", "lineno": 1387, "message": ""}, {"path": "/usr/lib/python3.12/contextlib.py", "lineno": 137, "message": "in __enter__"}, {"path": "/usr/lib/python3.12/unittest/mock.py", "lineno": 1369, "message": "in decoration_helper"}, {"path": "/usr/lib/python3.12/contextlib.py", "lineno": 526, "message": "in enter_context"}, {"path": "/usr/lib/python3.12/unittest/mock.py", "lineno": 1458, "message": "in __enter__"}, {"path": "/usr/lib/python3.12/unittest/mock.py", "lineno": 1431, "message": "AttributeError"}], "longrepr": "args = (), keywargs = {}\n\n    @wraps(func)\n    def patched(*args, **keywargs):\n>       with self.decoration_helper(patched,\n                                    args,\n                                    keywargs) as (newargs, newkeywargs):\n\n/usr/lib/python3.12/unittest/mock.py:1387: \n_ _ _ _ _ _ _ _ _ _ _ _ _ _ _ _ _ _ _ _ _ _ _ _ _ _ _ _ _ _ _ _ _ _ _ _ _ _ _ _ \n/usr/lib/python3.12/contextlib.py:137: in __enter__\n    return next(self.gen)\n/usr/lib/python3.12/unittest/mock.py:1369: in decoration_helper\n    arg = exit_stack.enter_context(patching)\n/usr/lib/python3.12/contextlib.py:526: in enter_context\n    result = _enter(cm)\n/usr/lib/python3.12/unittest/mock.py:1458: in __enter__\n    original, local = self.get_original()\n_ _ _ _ _ _ _ _ _ _ _ _ _ _ _ _ _ _ _ _ _ _ _ _ _ _ _ _ _ _ _ _ _ _ _ _ _ _ _ _ \n\nself = <unittest.mock._patch object at 0x7715d402cfe0>\n\n    def get_original(self):\n        target = self.getter()\n        name = self.attribute\n    \n        original = DEFAULT\n        local = False\n    \n        try:\n            original = target.__dict__[name]\n        except (AttributeError, KeyError):\n            original = getattr(target, name, DEFAULT)\n        else:\n            local = True\n    \n        if name in _builtins and isinstance(target, ModuleType):\n            self.create = True\n    \n        if not self.create and original is DEFAULT:\n>           raise AttributeError(\n                \"%s does not have the attribute %r\" % (target, name)\n            )\nE           AttributeError: <module '__main__' from '/home/jayasree/e-commerce/venv/bin/pytest'> does not have the attribute 'settings'\n\n/usr/lib/python3.12/unittest/mock.py:1431: AttributeError"}, "teardown": {"duration": 0.00028195300183142535, "outcome": "passed"}}, {"nodeid": "test_failed1.py::test_send_email_smtp_host_is_none", "lineno": 722, "outcome": "failed", "keywords": ["test_send_email_smtp_host_is_none", "__wrapped__", "patchings", "test_failed1.py", "backend"], "setup": {"duration": 0.00011076499868067913, "outcome": "passed"}, "call": {"duration": 0.0003845729988825042, "outcome": "failed", "crash": {"path": "/usr/lib/python3.12/unittest/mock.py", "lineno": 1431, "message": "AttributeError: <module '__main__' from '/home/jayasree/e-commerce/venv/bin/pytest'> does not have the attribute 'settings'"}, "traceback": [{"path": "/usr/lib/python3.12/unittest/mock.py", "lineno": 1387, "message": ""}, {"path": "/usr/lib/python3.12/contextlib.py", "lineno": 137, "message": "in __enter__"}, {"path": "/usr/lib/python3.12/unittest/mock.py", "lineno": 1369, "message": "in decoration_helper"}, {"path": "/usr/lib/python3.12/contextlib.py", "lineno": 526, "message": "in enter_context"}, {"path": "/usr/lib/python3.12/unittest/mock.py", "lineno": 1458, "message": "in __enter__"}, {"path": "/usr/lib/python3.12/unittest/mock.py", "lineno": 1431, "message": "AttributeError"}], "longrepr": "args = (), keywargs = {}\n\n    @wraps(func)\n    def patched(*args, **keywargs):\n>       with self.decoration_helper(patched,\n                                    args,\n                                    keywargs) as (newargs, newkeywargs):\n\n/usr/lib/python3.12/unittest/mock.py:1387: \n_ _ _ _ _ _ _ _ _ _ _ _ _ _ _ _ _ _ _ _ _ _ _ _ _ _ _ _ _ _ _ _ _ _ _ _ _ _ _ _ \n/usr/lib/python3.12/contextlib.py:137: in __enter__\n    return next(self.gen)\n/usr/lib/python3.12/unittest/mock.py:1369: in decoration_helper\n    arg = exit_stack.enter_context(patching)\n/usr/lib/python3.12/contextlib.py:526: in enter_context\n    result = _enter(cm)\n/usr/lib/python3.12/unittest/mock.py:1458: in __enter__\n    original, local = self.get_original()\n_ _ _ _ _ _ _ _ _ _ _ _ _ _ _ _ _ _ _ _ _ _ _ _ _ _ _ _ _ _ _ _ _ _ _ _ _ _ _ _ \n\nself = <unittest.mock._patch object at 0x7715d402d160>\n\n    def get_original(self):\n        target = self.getter()\n        name = self.attribute\n    \n        original = DEFAULT\n        local = False\n    \n        try:\n            original = target.__dict__[name]\n        except (AttributeError, KeyError):\n            original = getattr(target, name, DEFAULT)\n        else:\n            local = True\n    \n        if name in _builtins and isinstance(target, ModuleType):\n            self.create = True\n    \n        if not self.create and original is DEFAULT:\n>           raise AttributeError(\n                \"%s does not have the attribute %r\" % (target, name)\n            )\nE           AttributeError: <module '__main__' from '/home/jayasree/e-commerce/venv/bin/pytest'> does not have the attribute 'settings'\n\n/usr/lib/python3.12/unittest/mock.py:1431: AttributeError"}, "teardown": {"duration": 0.00021171499975025654, "outcome": "passed"}}, {"nodeid": "test_failed1.py::test_send_email_smtp_port_is_zero", "lineno": 755, "outcome": "failed", "keywords": ["test_send_email_smtp_port_is_zero", "__wrapped__", "patchings", "test_failed1.py", "backend"], "setup": {"duration": 9.827600297285244e-05, "outcome": "passed"}, "call": {"duration": 0.00014647600255557336, "outcome": "failed", "crash": {"path": "/usr/lib/python3.12/unittest/mock.py", "lineno": 1431, "message": "AttributeError: <module '__main__' from '/home/jayasree/e-commerce/venv/bin/pytest'> does not have the attribute 'settings'"}, "traceback": [{"path": "/usr/lib/python3.12/unittest/mock.py", "lineno": 1387, "message": ""}, {"path": "/usr/lib/python3.12/contextlib.py", "lineno": 137, "message": "in __enter__"}, {"path": "/usr/lib/python3.12/unittest/mock.py", "lineno": 1369, "message": "in decoration_helper"}, {"path": "/usr/lib/python3.12/contextlib.py", "lineno": 526, "message": "in enter_context"}, {"path": "/usr/lib/python3.12/unittest/mock.py", "lineno": 1458, "message": "in __enter__"}, {"path": "/usr/lib/python3.12/unittest/mock.py", "lineno": 1431, "message": "AttributeError"}], "longrepr": "args = (), keywargs = {}\n\n    @wraps(func)\n    def patched(*args, **keywargs):\n>       with self.decoration_helper(patched,\n                                    args,\n                                    keywargs) as (newargs, newkeywargs):\n\n/usr/lib/python3.12/unittest/mock.py:1387: \n_ _ _ _ _ _ _ _ _ _ _ _ _ _ _ _ _ _ _ _ _ _ _ _ _ _ _ _ _ _ _ _ _ _ _ _ _ _ _ _ \n/usr/lib/python3.12/contextlib.py:137: in __enter__\n    return next(self.gen)\n/usr/lib/python3.12/unittest/mock.py:1369: in decoration_helper\n    arg = exit_stack.enter_context(patching)\n/usr/lib/python3.12/contextlib.py:526: in enter_context\n    result = _enter(cm)\n/usr/lib/python3.12/unittest/mock.py:1458: in __enter__\n    original, local = self.get_original()\n_ _ _ _ _ _ _ _ _ _ _ _ _ _ _ _ _ _ _ _ _ _ _ _ _ _ _ _ _ _ _ _ _ _ _ _ _ _ _ _ \n\nself = <unittest.mock._patch object at 0x7715d402d2e0>\n\n    def get_original(self):\n        target = self.getter()\n        name = self.attribute\n    \n        original = DEFAULT\n        local = False\n    \n        try:\n            original = target.__dict__[name]\n        except (AttributeError, KeyError):\n            original = getattr(target, name, DEFAULT)\n        else:\n            local = True\n    \n        if name in _builtins and isinstance(target, ModuleType):\n            self.create = True\n    \n        if not self.create and original is DEFAULT:\n>           raise AttributeError(\n                \"%s does not have the attribute %r\" % (target, name)\n            )\nE           AttributeError: <module '__main__' from '/home/jayasree/e-commerce/venv/bin/pytest'> does not have the attribute 'settings'\n\n/usr/lib/python3.12/unittest/mock.py:1431: AttributeError"}, "teardown": {"duration": 0.00031346900141215883, "outcome": "passed"}}, {"nodeid": "test_failed1.py::test_send_email_authentication_fails", "lineno": 788, "outcome": "failed", "keywords": ["test_send_email_authentication_fails", "__wrapped__", "patchings", "test_failed1.py", "backend"], "setup": {"duration": 0.0001808260021789465, "outcome": "passed"}, "call": {"duration": 0.0002052019990514964, "outcome": "failed", "crash": {"path": "/usr/lib/python3.12/unittest/mock.py", "lineno": 1431, "message": "AttributeError: <module '__main__' from '/home/jayasree/e-commerce/venv/bin/pytest'> does not have the attribute 'settings'"}, "traceback": [{"path": "/usr/lib/python3.12/unittest/mock.py", "lineno": 1387, "message": ""}, {"path": "/usr/lib/python3.12/contextlib.py", "lineno": 137, "message": "in __enter__"}, {"path": "/usr/lib/python3.12/unittest/mock.py", "lineno": 1369, "message": "in decoration_helper"}, {"path": "/usr/lib/python3.12/contextlib.py", "lineno": 526, "message": "in enter_context"}, {"path": "/usr/lib/python3.12/unittest/mock.py", "lineno": 1458, "message": "in __enter__"}, {"path": "/usr/lib/python3.12/unittest/mock.py", "lineno": 1431, "message": "AttributeError"}], "longrepr": "args = (), keywargs = {}\n\n    @wraps(func)\n    def patched(*args, **keywargs):\n>       with self.decoration_helper(patched,\n                                    args,\n                                    keywargs) as (newargs, newkeywargs):\n\n/usr/lib/python3.12/unittest/mock.py:1387: \n_ _ _ _ _ _ _ _ _ _ _ _ _ _ _ _ _ _ _ _ _ _ _ _ _ _ _ _ _ _ _ _ _ _ _ _ _ _ _ _ \n/usr/lib/python3.12/contextlib.py:137: in __enter__\n    return next(self.gen)\n/usr/lib/python3.12/unittest/mock.py:1369: in decoration_helper\n    arg = exit_stack.enter_context(patching)\n/usr/lib/python3.12/contextlib.py:526: in enter_context\n    result = _enter(cm)\n/usr/lib/python3.12/unittest/mock.py:1458: in __enter__\n    original, local = self.get_original()\n_ _ _ _ _ _ _ _ _ _ _ _ _ _ _ _ _ _ _ _ _ _ _ _ _ _ _ _ _ _ _ _ _ _ _ _ _ _ _ _ \n\nself = <unittest.mock._patch object at 0x7715d402d460>\n\n    def get_original(self):\n        target = self.getter()\n        name = self.attribute\n    \n        original = DEFAULT\n        local = False\n    \n        try:\n            original = target.__dict__[name]\n        except (AttributeError, KeyError):\n            original = getattr(target, name, DEFAULT)\n        else:\n            local = True\n    \n        if name in _builtins and isinstance(target, ModuleType):\n            self.create = True\n    \n        if not self.create and original is DEFAULT:\n>           raise AttributeError(\n                \"%s does not have the attribute %r\" % (target, name)\n            )\nE           AttributeError: <module '__main__' from '/home/jayasree/e-commerce/venv/bin/pytest'> does not have the attribute 'settings'\n\n/usr/lib/python3.12/unittest/mock.py:1431: AttributeError"}, "teardown": {"duration": 0.00016786199921625666, "outcome": "passed"}}, {"nodeid": "test_failed1.py::test_send_email_conflicting_tls_ssl_settings", "lineno": 821, "outcome": "failed", "keywords": ["test_send_email_conflicting_tls_ssl_settings", "__wrapped__", "patchings", "test_failed1.py", "backend"], "setup": {"duration": 8.627799979876727e-05, "outcome": "passed"}, "call": {"duration": 0.0001348309997410979, "outcome": "failed", "crash": {"path": "/usr/lib/python3.12/unittest/mock.py", "lineno": 1431, "message": "AttributeError: <module '__main__' from '/home/jayasree/e-commerce/venv/bin/pytest'> does not have the attribute 'settings'"}, "traceback": [{"path": "/usr/lib/python3.12/unittest/mock.py", "lineno": 1387, "message": ""}, {"path": "/usr/lib/python3.12/contextlib.py", "lineno": 137, "message": "in __enter__"}, {"path": "/usr/lib/python3.12/unittest/mock.py", "lineno": 1369, "message": "in decoration_helper"}, {"path": "/usr/lib/python3.12/contextlib.py", "lineno": 526, "message": "in enter_context"}, {"path": "/usr/lib/python3.12/unittest/mock.py", "lineno": 1458, "message": "in __enter__"}, {"path": "/usr/lib/python3.12/unittest/mock.py", "lineno": 1431, "message": "AttributeError"}], "longrepr": "args = (), keywargs = {}\n\n    @wraps(func)\n    def patched(*args, **keywargs):\n>       with self.decoration_helper(patched,\n                                    args,\n                                    keywargs) as (newargs, newkeywargs):\n\n/usr/lib/python3.12/unittest/mock.py:1387: \n_ _ _ _ _ _ _ _ _ _ _ _ _ _ _ _ _ _ _ _ _ _ _ _ _ _ _ _ _ _ _ _ _ _ _ _ _ _ _ _ \n/usr/lib/python3.12/contextlib.py:137: in __enter__\n    return next(self.gen)\n/usr/lib/python3.12/unittest/mock.py:1369: in decoration_helper\n    arg = exit_stack.enter_context(patching)\n/usr/lib/python3.12/contextlib.py:526: in enter_context\n    result = _enter(cm)\n/usr/lib/python3.12/unittest/mock.py:1458: in __enter__\n    original, local = self.get_original()\n_ _ _ _ _ _ _ _ _ _ _ _ _ _ _ _ _ _ _ _ _ _ _ _ _ _ _ _ _ _ _ _ _ _ _ _ _ _ _ _ \n\nself = <unittest.mock._patch object at 0x7715d402d5e0>\n\n    def get_original(self):\n        target = self.getter()\n        name = self.attribute\n    \n        original = DEFAULT\n        local = False\n    \n        try:\n            original = target.__dict__[name]\n        except (AttributeError, KeyError):\n            original = getattr(target, name, DEFAULT)\n        else:\n            local = True\n    \n        if name in _builtins and isinstance(target, ModuleType):\n            self.create = True\n    \n        if not self.create and original is DEFAULT:\n>           raise AttributeError(\n                \"%s does not have the attribute %r\" % (target, name)\n            )\nE           AttributeError: <module '__main__' from '/home/jayasree/e-commerce/venv/bin/pytest'> does not have the attribute 'settings'\n\n/usr/lib/python3.12/unittest/mock.py:1431: AttributeError"}, "teardown": {"duration": 0.00015723600154160522, "outcome": "passed"}}, {"nodeid": "test_failed1.py::test_send_email_unexpected_message_send_exception", "lineno": 854, "outcome": "failed", "keywords": ["test_send_email_unexpected_message_send_exception", "__wrapped__", "patchings", "test_failed1.py", "backend"], "setup": {"duration": 8.598599742981605e-05, "outcome": "passed"}, "call": {"duration": 0.0001420660009898711, "outcome": "failed", "crash": {"path": "/usr/lib/python3.12/unittest/mock.py", "lineno": 1431, "message": "AttributeError: <module '__main__' from '/home/jayasree/e-commerce/venv/bin/pytest'> does not have the attribute 'settings'"}, "traceback": [{"path": "/usr/lib/python3.12/unittest/mock.py", "lineno": 1387, "message": ""}, {"path": "/usr/lib/python3.12/contextlib.py", "lineno": 137, "message": "in __enter__"}, {"path": "/usr/lib/python3.12/unittest/mock.py", "lineno": 1369, "message": "in decoration_helper"}, {"path": "/usr/lib/python3.12/contextlib.py", "lineno": 526, "message": "in enter_context"}, {"path": "/usr/lib/python3.12/unittest/mock.py", "lineno": 1458, "message": "in __enter__"}, {"path": "/usr/lib/python3.12/unittest/mock.py", "lineno": 1431, "message": "AttributeError"}], "longrepr": "args = (), keywargs = {}\n\n    @wraps(func)\n    def patched(*args, **keywargs):\n>       with self.decoration_helper(patched,\n                                    args,\n                                    keywargs) as (newargs, newkeywargs):\n\n/usr/lib/python3.12/unittest/mock.py:1387: \n_ _ _ _ _ _ _ _ _ _ _ _ _ _ _ _ _ _ _ _ _ _ _ _ _ _ _ _ _ _ _ _ _ _ _ _ _ _ _ _ \n/usr/lib/python3.12/contextlib.py:137: in __enter__\n    return next(self.gen)\n/usr/lib/python3.12/unittest/mock.py:1369: in decoration_helper\n    arg = exit_stack.enter_context(patching)\n/usr/lib/python3.12/contextlib.py:526: in enter_context\n    result = _enter(cm)\n/usr/lib/python3.12/unittest/mock.py:1458: in __enter__\n    original, local = self.get_original()\n_ _ _ _ _ _ _ _ _ _ _ _ _ _ _ _ _ _ _ _ _ _ _ _ _ _ _ _ _ _ _ _ _ _ _ _ _ _ _ _ \n\nself = <unittest.mock._patch object at 0x7715d402d760>\n\n    def get_original(self):\n        target = self.getter()\n        name = self.attribute\n    \n        original = DEFAULT\n        local = False\n    \n        try:\n            original = target.__dict__[name]\n        except (AttributeError, KeyError):\n            original = getattr(target, name, DEFAULT)\n        else:\n            local = True\n    \n        if name in _builtins and isinstance(target, ModuleType):\n            self.create = True\n    \n        if not self.create and original is DEFAULT:\n>           raise AttributeError(\n                \"%s does not have the attribute %r\" % (target, name)\n            )\nE           AttributeError: <module '__main__' from '/home/jayasree/e-commerce/venv/bin/pytest'> does not have the attribute 'settings'\n\n/usr/lib/python3.12/unittest/mock.py:1431: AttributeError"}, "teardown": {"duration": 0.00017792200014810078, "outcome": "passed"}}]}